Workbook

Sheet PDRB ADHK
A1: Satuan Milyar rupiah | B1: DIY | F1: Banten | J1: DKI Jakarta | N1: Jawa Barat | R1: Jawa Tengah | V1: Jawa Timur | Z1: TOTAL JAWA
B2: 2022 | C2: 2023 | D2: 2024 | E2: 2025 | F2: 2022 | G2: 2023 | H2: 2024 | I2: 2025 | J2: 2022 | K2: 2023 | L2: 2024 | M2: 2025** | N2: 2022 | O2: 2023 | P2: 2024 | Q2: 2025*** | R2: 2022 | S2: 2023 | T2: 2024 | U2: 2025 | V2: 2022 | W2: 2023 | X2: 2024 | Y2: 2025 | Z2: 2022 | AA2: 2023 | AB2: 2024 | AC2: 2025
A3: Pertanian. Kehutanan. dan Perikanan | B3: 9077.78 | C3: 9194.04 | D3: 9206.49 | E3: 9791.83 | F3: 26485.81 | G3: 26532.32 | H3: 26703.4 | I3: 29266.23 | J3: 1501.26 | K3: 1442.05 | L3: 1516.6 | M3: 1561.67 | N3: 113186.4 | O3: 113308.53 | P3: 115104.77 | Q3: 126696.5 | R3: 130762.52 | S3: 131330.54 | T3: 133162.54 | U3: 139530.4 | V3: 173747.56 | W3: 177668.37 | X3: 177809.48 | Y3: 186662.71 | Z3: =B3+F3+J3+N3+R3+V3 -> 454761.33 | AA3: =C3+G3+K3+O3+S3+W3 -> 459475.85 | AB3: =D3+H3+L3+P3+T3+X3 -> 463503.28 | AC3: =E3+I3+M3+Q3+U3+Y3 -> 493509.34
A4: Pertambangan dan Penggalian | B4: 501.03 | C4: 517.33 | D4: 557.4 | E4: 591.97 | F4: 2208.48 | G4: 1844.63 | H4: 1713.75 | I4: 1728.33 | J4: 2400.31 | K4: 2094.15 | L4: 1983.75 | M4: 1830.18 | N4: 23880.32 | O4: 23857.09 | P4: 23842.6 | Q4: 23723.09 | R4: 20942.66 | S4: 21232.09 | T4: 21833.06 | U4: 22315.21 | V4: 71865.2 | W4: 73057.78 | X4: 72582.57 | Y4: 73673.07 | Z4: =B4+F4+J4+N4+R4+V4 -> 121798 | AA4: =C4+G4+K4+O4+S4+W4 -> 122603.07 | AB4: =D4+H4+L4+P4+T4+X4 -> 122513.13 | AC4: =E4+I4+M4+Q4+U4+Y4 -> 123861.85
A5: Industri Pengolahan | B5: 12890.39 | C5: 13441.25 | D5: 13950.28 | E5: 14559.81 | F5: 160616.13 | G5: 169934.05 | H5: 178397.5 | I5: 187979.82 | J5: 228741.59 | K5: 232991.97 | L5: 235646 | M5: 239531.41 | N5: 683420.22 | O5: 715806.62 | P5: 741041.45 | Q5: 762103.15 | R5: 346169.65 | S5: 361111.03 | T5: 373837.72 | U5: 389026.51 | V5: 536394.03 | W5: 558448.65 | X5: 588598.82 | Y5: 623803.37 | Z5: =B5+F5+J5+N5+R5+V5 -> 1968232 | AA5: =C5+G5+K5+O5+S5+W5 -> 2051733.6 | AB5: =D5+H5+L5+P5+T5+X5 -> 2131471.8 | AC5: =E5+I5+M5+Q5+U5+Y5 -> 2217004.1
A6: Pengadaan Listrik dan Gas | B6: 178.22 | C6: 191.26 | D6: 211.67 | E6: 221.32 | F6: 4639.58 | G6: 4571.07 | H6: 4156.25 | I6: 4248.46 | J6: 4261.4 | K6: 3961.69 | L6: 3315.23 | M6: 2901.2 | N6: 5843.37 | O6: 5854.08 | P6: 5818.98 | Q6: 5916.01 | R6: 1214.86 | S6: 1297.42 | T6: 1387.68 | U6: 1448.95 | V6: 5065.01 | W6: 6282.63 | X6: 6717.94 | Y6: 7060.88 | Z6: =B6+F6+J6+N6+R6+V6 -> 21202.44 | AA6: =C6+G6+K6+O6+S6+W6 -> 22158.15 | AB6: =D6+H6+L6+P6+T6+X6 -> 21607.75 | AC6: =E6+I6+M6+Q6+U6+Y6 -> 21796.82
A7: Pengadaan Air. Pengelolaan Sampah. Limbah dan Daur Ulang | B7: 114.64 | C7: 118.57 | D7: 119.62 | E7: 118.96 | F7: 512.65 | G7: 540.27 | H7: 561.21 | I7: 585.9 | J7: 777.42 | K7: 826.6 | L7: 830.59 | M7: 800.67 | N7: 1456.85 | O7: 1495.07 | P7: 1577.05 | Q7: 1618.71 | R7: 752.41 | S7: 783.02 | T7: 800.9 | U7: 811.85 | V7: 1800.78 | W7: 1853.34 | X7: 1894.78 | Y7: 1962.12 | Z7: =B7+F7+J7+N7+R7+V7 -> 5414.75 | AA7: =C7+G7+K7+O7+S7+W7 -> 5616.87 | AB7: =D7+H7+L7+P7+T7+X7 -> 5784.15 | AC7: =E7+I7+M7+Q7+U7+Y7 -> 5898.21
A8: Konstruksi | B8: 11193.38 | C8: 11732.07 | D8: 12713.05 | E8: 13717.54 | F8: 51944.23 | G8: 52700.7 | H8: 55803.68 | I8: 59089.91 | J8: 211217.76 | K8: 216505.24 | L8: 231632.64 | M8: 238914.21 | N8: 126184.39 | O8: 133549.61 | P8: 143014.89 | Q8: 150684.6 | R8: 108657.61 | S8: 115250.87 | T8: 124441.81 | U8: 132673.93 | V8: 162018.82 | W8: 170190.58 | X8: 181960.11 | Y8: 190304.86 | Z8: =B8+F8+J8+N8+R8+V8 -> 671216.19 | AA8: =C8+G8+K8+O8+S8+W8 -> 699929.07 | AB8: =D8+H8+L8+P8+T8+X8 -> 749566.18 | AC8: =E8+I8+M8+Q8+U8+Y8 -> 785385.05
A9: Perdagangan Besar dan Eceran; Reparasi Mobil dan Sepeda Motor | B9: 8779.73 | C9: 9159.47 | D9: 9521.98 | E9: 10024.25 | F9: 64030.67 | G9: 66574.78 | H9: 69454.87 | I9: 72655.41 | J9: 307754.12 | K9: 321661.05 | L9: 343770.7 | M9: 362681.18 | N9: 230532.56 | O9: 240583.84 | P9: 252244.61 | Q9: 264862.53 | R9: 153670.44 | S9: 161240.41 | T9: 167931.17 | U9: 175700.39 | V9: 333626.69 | W9: 352837.67 | X9: 368875.69 | Y9: 383580.62 | Z9: =B9+F9+J9+N9+R9+V9 -> 1098394.2 | AA9: =C9+G9+K9+O9+S9+W9 -> 1152057.2 | AB9: =D9+H9+L9+P9+T9+X9 -> 1211799 | AC9: =E9+I9+M9+Q9+U9+Y9 -> 1269504.4
A10: Transportasi dan Pergudangan | B10: 5287.74 | C10: 5822.82 | D10: 6186.17 | E10: 6530.34 | F10: 27947.76 | G10: 31433.2 | H10: 33428.91 | I10: 34833.14 | J10: 74214.76 | K10: 84642.25 | L10: 90533.4 | M10: 98400.67 | N10: 75521.57 | O10: 83777.21 | P10: 94113.89 | Q10: 104938.19 | R10: 42103.03 | S10: 45523.39 | T10: 48052.76 | U10: 51285.06 | V10: 53240.33 | W10: 60314.16 | X10: 66044.82 | Y10: 70889.1 | Z10: =B10+F10+J10+N10+R10+V10 -> 278315.19 | AA10: =C10+G10+K10+O10+S10+W10 -> 311513.03 | AB10: =D10+H10+L10+P10+T10+X10 -> 338359.95 | AC10: =E10+I10+M10+Q10+U10+Y10 -> 366876.5
A11: Penyediaan Akomodasi dan Makan Minum | B11: 10259.81 | C11: 11173.46 | D11: 12131.02 | E11: 12899.6 | F11: 12249.58 | G11: 13284.07 | H11: 14221.36 | I11: 15157.59 | J11: 91152.68 | K11: 99983.06 | L11: 108295.65 | M11: 118398.38 | N11: 42972.84 | O11: 46721.89 | P11: 49724.89 | Q11: 54866.88 | R11: 38132.45 | S11: 42417.2 | T11: 46670.27 | U11: 51617.3 | V11: 9452.21 | W11: 101732.19 | X11: 108833.45 | Y11: 117602.95 | Z11: =B11+F11+J11+N11+R11+V11 -> 204219.57 | AA11: =C11+G11+K11+O11+S11+W11 -> 315311.87 | AB11: =D11+H11+L11+P11+T11+X11 -> 339876.64 | AC11: =E11+I11+M11+Q11+U11+Y11 -> 370542.7
A12: Informasi dan Komunikasi | B12: 16907.39 | C12: 17631.3 | D12: 18396.74 | E12: 19195.07 | F12: 33161.9 | G12: 35734.64 | H12: 37823.43 | I12: 39950.35 | J12: 262247.28 | K12: 281781.27 | L12: 295297.83 | M12: 313673.07 | N12: 97480.64 | O12: 105146 | P12: 113765.59 | Q12: 124147.98 | R12: 63846.51 | S12: 70658.78 | T12: 77416.08 | U12: 84182.23 | V12: 119126.09 | W12: 126994.5 | X12: 135158.83 | Y12: 145374.43 | Z12: =B12+F12+J12+N12+R12+V12 -> 592769.81 | AA12: =C12+G12+K12+O12+S12+W12 -> 637946.49 | AB12: =D12+H12+L12+P12+T12+X12 -> 677858.5 | AC12: =E12+I12+M12+Q12+U12+Y12 -> 726523.13
A13: Jasa Keuangan dan Asuransi | B13: 4018.73 | C13: 4432.25 | D13: 4721.39 | E13: 4794.84 | F13: 14912.11 | G13: 14810 | H13: 14850.57 | I13: 14594.36 | J13: 210508.45 | K13: 221857.65 | L13: 233740.3 | M13: 242701.8 | N13: 38743.11 | O13: 40184.13 | P13: 41870.17 | Q13: 43238.82 | R13: 27690.76 | S13: 28289.1 | T13: 28899.58 | U13: 30519.47 | V13: 43096.15 | W13: 44731.09 | X13: 46473.15 | Y13: 47512.44 | Z13: =B13+F13+J13+N13+R13+V13 -> 338969.31 | AA13: =C13+G13+K13+O13+S13+W13 -> 354304.22 | AB13: =D13+H13+L13+P13+T13+X13 -> 370555.16 | AC13: =E13+I13+M13+Q13+U13+Y13 -> 383361.73
A14: Real Estate | B14: 7864.69 | C14: 8155.53 | D14: 8487.82 | E14: 8831.62 | F14: 44509.24 | G14: 46071.63 | H14: 47716.22 | I14: 50549.62 | J14: 122960.43 | K14: 123874.01 | L14: 125748.53 | M14: 129233.11 | N14: 22993.05 | O14: 24426.12 | P14: 26046.99 | Q14: 28187.87 | R14: 20107.1 | S14: 21494.52 | T14: 22764.06 | U14: 24042.7 | V14: 31618.65 | W14: 32469.01 | X14: 33414.39 | Y14: 34538.09 | Z14: =B14+F14+J14+N14+R14+V14 -> 250053.16 | AA14: =C14+G14+K14+O14+S14+W14 -> 256490.82 | AB14: =D14+H14+L14+P14+T14+X14 -> 264178.01 | AC14: =E14+I14+M14+Q14+U14+Y14 -> 275383.01
... A19: Jasa Lainnya | B19: 3412.77 | C19: 3652.74 | D19: 3775.49 | E19: 4048.02 | F19: 7198 | G19: 7873.42 | H19: 8270.15 | I19: 8731.87 | J19: 78134.58 | K19: 87201.78 | L19: 91930.32 | M19: 99711.9 | N19: 35559.49 | O19: 38253.41 | P19: 41286.15 | Q19: 44975.22 | R19: 17963.16 | S19: 19294.49 | T19: 20609.68 | U19: 22288.53 | V19: 24250.11 | W19: 26492.18 | X19: 28759.88 | Y19: 31037.36 | Z19: =B19+F19+J19+N19+R19+V19 -> 166518.11 | AA19: =C19+G19+K19+O19+S19+W19 -> 182768.02 | AB19: =D19+H19+L19+P19+T19+X19 -> 194631.67 | AC19: =E19+I19+M19+Q19+U19+Y19 -> 210792.9
A20: TOTAL | B20: =SUM(B3:B19) -> 112901.34 | C20: =SUM(C3:C19) -> 118625.55 | D20: =SUM(D3:D19) -> 124590.44 | E20: =SUM(E3:E19) -> 131435.93 | F20: =SUM(F3:F19) -> 484131.21 | G20: =SUM(G3:G19) -> 507425.74 | H20: =SUM(H3:H19) -> 531735.24 | I20: =SUM(I3:I19) -> 560270.88 | ... O20: =SUM(O3:O19) -> 1669416.9 | P20: 1752124.2 | Q20: =SUM(Q3:Q19) -> 1845316.7 | R20: =SUM(R3:R19) -> 1050278.1 | S20: =SUM(S3:S19) -> 1102437.5 | T20: =SUM(T3:T19) -> 1156998.9 | U20: =SUM(U3:U19) -> 1219148.6 | V20: =SUM(V3:V19) -> 1673174.9 | W20: =SUM(W3:W19) -> 1844808.7 | X20: =SUM(X3:X19) -> 1935810.1 | ... AC20: =SUM(AC3:AC19) -> 8058370.8

Sheet PDRB ADHB
A1: Satuan Milyar rupiah | B1: DIY | F1: Banten | J1: DKI Jakarta | N1: Jawa Barat | R1: Jawa Tengah | V1: Jawa Timur | Z1: Total Jawa
B2: 2022 | C2: 2023 | D2: 2024 | E2: 2025 | F2: 2022 | G2: 2023 | H2: 2024 | I2: 2025 | J2: 2022 | K2: 2023 | L2: 2024* | M2: 2025** | N2: 2022 | O2: 2023 | P2: 2024 | Q2: 2025*** | R2: 2022 | S2: 2023 | T2: 2024 | U2: 2025 | V2: 2022 | W2: 2023 | X2: 2024 | Y2: 2025 | Z2: 2022 | AA2: 2023 | AB2: 2024 | AC2: 2025
A3: Pertanian. Kehutanan. dan Perikanan | B3: 16525.78 | C3: 18541.32 | D3: 19266.67 | E3: 21082.58 | F3: 44050.68 | G3: 46608.45 | H3: 49367.5 | I3: 55984.25 | J3: 2530.73 | K3: 2516.65 | L3: 2762.53 | M3: 2762.53 | N3: 207716.66 | O3: 221650.61 | P3: 237631.6 | Q3: 267710.3 | R3: 211490.54 | S3: 224291.41 | T3: 237348.86 | U3: 253907.09 | V3: 303510.39 | W3: 326087.35 | X3: 337697.52 | Y3: 365375.14 | Z3: =SUM(B3,F3,J3,N3,R3,V3) -> 785824.78 | AA3: =SUM(C3,G3,K3,O3,S3,W3) -> 839695.79 | AB3: =SUM(D3,H3,L3,P3,T3,X3) -> 884074.68 | AC3: =SUM(E3,I3,M3,Q3,U3,Y3) -> 966821.89
A4: Pertambangan dan Penggalian | B4: 713.77 | C4: 799.92 | D4: 871.35 | E4: 791.27 | F4: 4142.46 | G4: 3504.21 | H4: 3321.9 | I4: 3441.02 | J4: 8031.15 | K4: 6005.63 | L4: 5717.42 | M4: 5717.42 | N4: 27934.5 | O4: 26089.3 | P4: 27360.32 | Q4: 27600.49 | R4: 37723.92 | S4: 38102.94 | T4: 39211.8 | U4: 40556.56 | V4: 119698.47 | W4: 112701.63 | X4: 113344.46 | Y4: 113099.01 | Z4: =SUM(B4,F4,J4,N4,R4,V4) -> 198244.27 | AA4: =SUM(C4,G4,K4,O4,S4,W4) -> 187203.63 | AB4: =SUM(D4,H4,L4,P4,T4,X4) -> 189827.25 | AC4: =SUM(E4,I4,M4,Q4,U4,Y4) -> 191205.77
A5: Industri Pengolahan | B5: 19775.46 | C5: 21352.59 | D5: 22927.55 | E5: 24552.34 | F5: 227665.58 | G5: 246265.69 | H5: 265140.7 | I5: 285314.72 | J5: 391219.26 | K5: 408799.84 | L5: 422940.32 | M5: 422940.32 | N5: 1023400.8 | O5: 1099081.2 | P5: 1168548.2 | Q5: 1227809 | R5: 529181.82 | S5: 576208.65 | T5: 614658.98 | U5: 648749.29 | V5: 835393.31 | W5: 901185.69 | X5: 977507.54 | Y5: 1065685.8 | Z5: =SUM(B5,F5,J5,N5,R5,V5) -> 3026636.2 | AA5: =SUM(C5,G5,K5,O5,S5,W5) -> 3252893.7 | AB5: =SUM(D5,H5,L5,P5,T5,X5) -> 3471723.3 | AC5: =SUM(E5,I5,M5,Q5,U5,Y5) -> 3675051.5
A6: Pengadaan Listrik dan Gas | B6: 223.58 | C6: 250 | D6: 277.56 | E6: 292.22 | F6: 13017.8 | G6: 12785.13 | H6: 10831.56 | I6: 11372.92 | J6: 7486.94 | K6: 6878.99 | L6: 5628.35 | M6: 5628.35 | N6: 12161.53 | O6: 12221.17 | P6: 12059.32 | Q6: 12551.2 | R6: 1438 | S6: 1556.85 | T6: 1675.83 | U6: 1752.77 | V6: 8042.88 | W6: 10374.52 | X6: 11181.77 | Y6: 11981.83 | Z6: =SUM(B6,F6,J6,N6,R6,V6) -> 42370.73 | AA6: =SUM(C6,G6,K6,O6,S6,W6) -> 44066.66 | AB6: =SUM(D6,H6,L6,P6,T6,X6) -> 41654.39 | AC6: =SUM(E6,I6,M6,Q6,U6,Y6) -> 43579.29
A7: Pengadaan Air. Pengelolaan Sampah. Limbah dan Daur Ulang | B7: 162.57 | C7: 171.98 | D7: 174.22 | E7: 174.28 | F7: 612.68 | G7: 652.28 | H7: 718.35 | I7: 769.82 | J7: 984.18 | K7: 1057.43 | L7: 1121.37 | M7: 1121.37 | N7: 2485.54 | O7: 2575.78 | P7: 2872.12 | Q7: 3044.19 | R7: 938.29 | S7: 985.79 | T7: 1066.34 | U7: 1123.96 | V7: 2443.2 | W7: 2541.86 | X7: 2626.96 | Y7: 2763.35 | Z7: =SUM(B7,F7,J7,N7,R7,V7) -> 7626.46 | AA7: =SUM(C7,G7,K7,O7,S7,W7) -> 7985.12 | AB7: =SUM(D7,H7,L7,P7,T7,X7) -> 8579.36 | AC7: =SUM(E7,I7,M7,Q7,U7,Y7) -> 8996.97
A8: Konstruksi | B8: 16440.15 | C8: 17036.95 | D8: 18627.62 | E8: 20420.61 | F8: 91184.67 | G8: 95666.94 | H8: 102165.15 | I8: 110523.6 | J8: 351920.99 | K8: 372447.93 | L8: 401305.8 | M8: 401305.8 | N8: 202276.62 | O8: 221150.71 | P8: 238500.79 | Q8: 253691.2 | R8: 172199.81 | S8: 190384.35 | T8: 207039.33 | U8: 222900.55 | V8: 246876.37 | W8: 263243.87 | X8: 284121.28 | Y8: 299579.06 | Z8: =SUM(B8,F8,J8,N8,R8,V8) -> 1080898.6 | AA8: =SUM(C8,G8,K8,O8,S8,W8) -> 1159930.8 | AB8: =SUM(D8,H8,L8,P8,T8,X8) -> 1251760 | AC8: =SUM(E8,I8,M8,Q8,U8,Y8) -> 1308420.8
A9: Perdagangan Besar dan Eceran; Reparasi Mobil dan Sepeda Motor | B9: 13677.56 | C9: 14768.7 | D9: 15623.23 | E9: 16761.57 | F9: 93547.29 | G9: 101006.64 | H9: 108163.85 | I9: 115667.09 | J9: 555567.92 | K9: 608311.63 | L9: 662471.32 | M9: 662471.32 | N9: 348996.55 | O9: 378832.69 | P9: 408257.19 | Q9: 438021.6 | R9: 212208.01 | S9: 230723.26 | T9: 245140.47 | U9: 262081.27 | V9: 509889.56 | W9: 558385.86 | X9: 596083.66 | Y9: 631235.53 | Z9: =SUM(B9,F9,J9,N9,R9,V9) -> 1733886.9 | AA9: =SUM(C9,G9,K9,O9,S9,W9) -> 1892028.8 | AB9: =SUM(D9,H9,L9,P9,T9,X9) -> 2035739.7 | AC9: =SUM(E9,I9,M9,Q9,U9,Y9) -> 2126238.4
A10: Transportasi dan Pergudangan | B10: 8483.54 | C10: 10135.39 | D10: 11282.92 | E10: 11933.75 | F10: 71161.82 | G10: 90542.7 | H10: 100200.91 | I10: 103587.51 | J10: 126971.27 | K10: 151850.8 | L10: 166936.1 | M10: 166936.1 | N10: 130202.05 | O10: 155099.82 | P10: 176286.29 | Q10: 200138.9 | R10: 59256.75 | S10: 69538.67 | T10: 74443.94 | U10: 80201.66 | V10: 96434.87 | W10: 119171.36 | X10: 132252.92 | Y10: 142333.91 | Z10: =SUM(B10,F10,J10,N10,R10,V10) -> 492510.3 | AA10: =SUM(C10,G10,K10,O10,S10,W10) -> 596338.74 | AB10: =SUM(D10,H10,L10,P10,T10,X10) -> 661403.08 | AC10: =SUM(E10,I10,M10,Q10,U10,Y10) -> 705131.83
A11: Penyediaan Akomodasi dan Makan Minum | B11: 16374.44 | C11: 18421.95 | D11: 20534.52 | E11: 22713.47 | F11: 17447.46 | G11: 19150.09 | H11: 21071.86 | I11: 22828.46 | J11: 143663.36 | K11: 161237.93 | L11: 178510.88 | M11: 178510.88 | N11: 69670.16 | O11: 79501.42 | P11: 86660.1 | Q11: 97413.82 | R11: 51316.31 | S11: 57757.14 | T11: 64731.32 | U11: 72617.6 | V11: 154142.37 | W11: 173189.33 | X11: 189716.7 | Y11: 208494.46 | Z11: =SUM(B11,F11,J11,N11,R11,V11) -> 452614.1 | AA11: =SUM(C11,G11,K11,O11,S11,W11) -> 509257.86 | AB11: =SUM(D11,H11,L11,P11,T11,X11) -> 561225.38 | AC11: =SUM(E11,I11,M11,Q11,U11,Y11) -> 602578.69
A12: Informasi dan Komunikasi | B12: 17073.16 | C12: 18110.08 | D12: 18931.12 | E12: 20056.23 | F12: 28218.24 | G12: 30601.82 | H12: 32734.19 | I12: 34663.22 | J12: 294865.58 | K12: 320987.64 | L12: 342477.64 | M12: 342477.64 | N12: 92644.33 | O12: 100002.58 | P12: 108134.62 | Q12: 117665 | R12: 62593.23 | S12: 69420.57 | T12: 76438.36 | U12: 83408.76 | V12: 135673.33 | W12: 145547.25 | X12: 156394.33 | Y12: 168566.56 | Z12: =SUM(B12,F12,J12,N12,R12,V12) -> 631067.87 | AA12: =SUM(C12,G12,K12,O12,S12,W12) -> 684669.94 | AB12: =SUM(D12,H12,L12,P12,T12,X12) -> 735110.26 | AC12: =SUM(E12,I12,M12,Q12,U12,Y12) -> 766837.41
A13: Jasa Keuangan dan Asuransi | B13: 6830.31 | C13: 7678.61 | D13: 8250.02 | E13: 8561.35 | F13: 25307.63 | G13: 25724.53 | H13: 26054.81 | I13: 25992.58 | J13: 352956.32 | K13: 382294.93 | L13: 408186.14 | M13: 408186.14 | N13: 69885.95 | O13: 74126.26 | P13: 78558.46 | Q13: 83737.81 | R13: 46920.61 | S13: 48965.2 | T13: 50560.09 | U13: 54552.68 | V13: 72592.53 | W13: 77073.8 | X13: 80978.2 | Y13: 84295.03 | Z13: =SUM(B13,F13,J13,N13,R13,V13) -> 574493.35 | AA13: =SUM(C13,G13,K13,O13,S13,W13) -> 615863.33 | AB13: =SUM(D13,H13,L13,P13,T13,X13) -> 652587.72 | AC13: =SUM(E13,I13,M13,Q13,U13,Y13) -> 665325.59
A14: Real Estate | B14: 11195.83 | C14: 11930.69 | D14: 12540.58 | E14: 13482.51 | F14: 60289.4 | G14: 64183.34 | H14: 67427.4 | I14: 73458.86 | J14: 186183.76 | K14: 193776 | L14: 200045.22 | M14: 200045.22 | N14: 28413.16 | O14: 30746.38 | P14: 32865.01 | Q14: 35902.46 | R14: 25420.79 | S14: 27455.79 | T14: 29153.89 | U14: 31091.49 | V14: 44748.26 | W14: 46496.44 | X14: 48278.29 | Y14: 51192.48 | Z14: =SUM(B14,F14,J14,N14,R14,V14) -> 356251.2 | AA14: =SUM(C14,G14,K14,O14,S14,W14) -> 374588.64 | AB14: =SUM(D14,H14,L14,P14,T14,X14) -> 390310.39 | AC14: =SUM(E14,I14,M14,Q14,U14,Y14) -> 405173.02
... A17: Jasa Pendidikan | B17: 13913.75 | C17: 15212.77 | D17: 16027.4 | E17: 17051 | F17: 24581.06 | G17: 26680.99 | H17: 29453.36 | I17: 31944.14 | J17: 149353.37 | K17: 150213.28 | L17: 159541.97 | M17: 159541.97 | N17: 80336.14 | O17: 86301.84 | P17: 92230.1 | Q17: 99553.07 | R17: 65985.53 | S17: 70550.28 | T17: 77978.57 | U17: 84860.79 | V17: 67704.93 | W17: 72543.67 | X17: 77115.59 | Y17: 83169.6 | Z17: =SUM(B17,F17,J17,N17,R17,V17) -> 401874.78 | AA17: =SUM(C17,G17,K17,O17,S17,W17) -> 421502.83 | AB17: =SUM(D17,H17,L17,P17,T17,X17) -> 452346.99 | AC17: =SUM(E17,I17,M17,Q17,U17,Y17) -> 476120.57
A18: Jasa Kesehatan dan Kegiatan Sosial | B18: 5131.07 | C18: 5789.17 | D18: 6253.69 | E18: 6789.31 | F18: 10687.98 | G18: 11.841.83 | H18: 13208.08 | I18: 13840.12 | J18: 70997.34 | K18: 76588.42 | L18: 82004.51 | M18: 82004.51 | N18: 19157.24 | O18: 20978.21 | P18: 22908.96 | Q18: 25573.7 | R18: 14372.31 | S18: 15533.75 | T18: 16932.97 | U18: 18109.07 | V18: 18875.47 | W18: 20154.16 | X18: 21473.36 | Y18: 23719.81 | Z18: =SUM(B18,F18,J18,N18,R18,V18) -> 139221.41 | AA18: =SUM(C18,G18,K18,O18,S18,W18) -> 139043.71 | AB18: =SUM(D18,H18,L18,P18,T18,X18) -> 162781.57 | AC18: =SUM(E18,I18,M18,Q18,U18,Y18) -> 170036.52
A19: Jasa Lainnya | B19: 4721.76 | C19: 5293.81 | D19: 5548.53 | E19: 6186.01 | F19: 12163.45 | G19: 13971.78 | H19: 14903.65 | I19: 16027.73 | J19: 128238.43 | K19: 149693.7 | L19: 159695.26 | M19: 159695.26 | N19: 52154.05 | O19: 58490.22 | P19: 66839.94 | Q19: 79766.91 | R19: 24413.4 | S19: 27022.68 | T19: 29586.58 | U19: 32949.35 | V19: 35552.39 | W19: 40663.65 | X19: 45132.22 | Y19: 51.099.95 | Z19: =SUM(B19,F19,J19,N19,R19,V19) -> 257243.48 | AA19: =SUM(C19,G19,K19,O19,S19,W19) -> 295135.84 | AB19: =SUM(D19,H19,L19,P19,T19,X19) -> 321706.18 | AC19: =SUM(E19,I19,M19,Q19,U19,Y19) -> 294625.26
A20: TOTAL | B20: =sum(B3:B19) -> 165724.52 | C20: =sum(C3:C19) -> 180746.4 | D20: =sum(D3:D19) -> 193561.95 | E20: =sum(E3:E19) -> 208133.81 | F20: =sum(F3:F19) -> 747223.58 | G20: =sum(G3:G19) -> 802282.49 | H20: =sum(H3:H19) -> 873626.26 | I20: =sum(I3:I19) -> 936203.97 | ... Y20: =sum(Y3:Y19) -> 3352066.9 | Z20: =SUM(B20,F20,J20,N20,R20,V20) -> 10814836 | AA20: =sum(AA3:AA19) -> 11700582 | AB20: =sum(AB3:AB19) -> 12556242 | AC20: =sum(AC3:AC19) -> 13157969

Sheet LQ ADHK
B1: Satuan Milyar rupiah | C1: DIY | G1: Banten | K1: DKI Jakarta | O1: Jawa Barat | S1: Jawa Tengah | W1: Jawa Timur | AA1: TOTAL JAWA
C2: 2022 | D2: 2023 | E2: 2024 | F2: 2025 | G2: 2022 | H2: 2023 | I2: 2024 | J2: 2025 | K2: 2022 | L2: 2023 | M2: 2024 | N2: 2025** | O2: 2022 | P2: 2023 | Q2: 2024 | R2: 2025*** | S2: 2022 | T2: 2023 | U2: 2024 | V2: 2025 | W2: 2022 | X2: 2023 | Y2: 2024 | Z2: 2025 | AA2: 2022 | AB2: 2023 | AC2: 2024 | AD2: 2025
B3: Pertanian. Kehutanan. dan Perikanan | C3: 9077.78 | D3: 9194.04 | E3: 9206.49 | F3: 9791.83 | G3: 26485.81 | H3: 26532.32 | I3: 26703.4 | J3: 29266.23 | K3: 1501.26 | L3: 1442.05 | M3: 1516.6 | N3: 1561.67 | O3: 113186.4 | P3: 113308.53 | Q3: 115104.77 | R3: 126696.5 | S3: 130762.52 | T3: 131330.54 | U3: 133162.54 | V3: 139530.4 | W3: 173747.56 | X3: 177668.37 | Y3: 177809.48 | Z3: 186662.71 | AA3: =C3+G3+K3+O3+S3+W3 -> 454761.33 | AB3: =D3+H3+L3+P3+T3+X3 -> 459475.85 | AC3: =E3+I3+M3+Q3+U3+Y3 -> 463503.28 | AD3: =F3+J3+N3+R3+V3+Z3 -> 493509.34
B4: Pertambangan dan Penggalian | C4: 501.03 | D4: 517.33 | E4: 557.4 | F4: 591.97 | G4: 2208.48 | H4: 1844.63 | I4: 1713.75 | J4: 1728.33 | K4: 2400.31 | L4: 2094.15 | M4: 1983.75 | N4: 1830.18 | O4: 23880.32 | P4: 23857.09 | Q4: 23842.6 | R4: 23723.09 | S4: 20942.66 | T4: 21232.09 | U4: 21833.06 | V4: 22315.21 | W4: 71865.2 | X4: 73057.78 | Y4: 72582.57 | Z4: 73673.07 | AA4: =C4+G4+K4+O4+S4+W4 -> 121798 | AB4: =D4+H4+L4+P4+T4+X4 -> 122603.07 | AC4: =E4+I4+M4+Q4+U4+Y4 -> 122513.13 | AD4: =F4+J4+N4+R4+V4+Z4 -> 123861.85
B5: Industri Pengolahan | C5: 12890.39 | D5: 13441.25 | E5: 13950.28 | F5: 14559.81 | G5: 160616.13 | H5: 169934.05 | I5: 178397.5 | J5: 187979.82 | K5: 228741.59 | L5: 232991.97 | M5: 235646 | N5: 239531.41 | O5: 683420.22 | P5: 715806.62 | Q5: 741041.45 | R5: 762103.15 | S5: 346169.65 | T5: 361111.03 | U5: 373837.72 | V5: 389026.51 | W5: 536394.03 | X5: 558448.65 | Y5: 588598.82 | Z5: 623803.37 | AA5: =C5+G5+K5+O5+S5+W5 -> 1968232 | AB5: =D5+H5+L5+P5+T5+X5 -> 2051733.6 | AC5: =E5+I5+M5+Q5+U5+Y5 -> 2131471.8 | AD5: =F5+J5+N5+R5+V5+Z5 -> 2217004.1
B6: Pengadaan Listrik dan Gas | C6: 178.22 | D6: 191.26 | E6: 211.67 | F6: 221.32 | G6: 4639.58 | H6: 4571.07 | I6: 4156.25 | J6: 4248.46 | K6: 4261.4 | L6: 3961.69 | M6: 3315.23 | N6: 2901.2 | O6: 5843.37 | P6: 5854.08 | Q6: 5818.98 | R6: 5916.01 | S6: 1214.86 | T6: 1297.42 | U6: 1387.68 | V6: 1448.95 | W6: 5065.01 | X6: 6282.63 | Y6: 6717.94 | Z6: 7060.88 | AA6: =C6+G6+K6+O6+S6+W6 -> 21202.44 | AB6: =D6+H6+L6+P6+T6+X6 -> 22158.15 | AC6: =E6+I6+M6+Q6+U6+Y6 -> 21607.75 | AD6: =F6+J6+N6+R6+V6+Z6 -> 21796.82
B7: Pengadaan Air. Pengelolaan Sampah. Limbah dan Daur Ulang | C7: 114.64 | D7: 118.57 | E7: 119.62 | F7: 118.96 | G7: 512.65 | H7: 540.27 | I7: 561.21 | J7: 585.9 | K7: 777.42 | L7: 826.6 | M7: 830.59 | N7: 800.67 | O7: 1456.85 | P7: 1495.07 | Q7: 1577.05 | R7: 1618.71 | S7: 752.41 | T7: 783.02 | U7: 800.9 | V7: 811.85 | W7: 1800.78 | X7: 1853.34 | Y7: 1894.78 | Z7: 1962.12 | AA7: =C7+G7+K7+O7+S7+W7 -> 5414.75 | AB7: =D7+H7+L7+P7+T7+X7 -> 5616.87 | AC7: =E7+I7+M7+Q7+U7+Y7 -> 5784.15 | AD7: =F7+J7+N7+R7+V7+Z7 -> 5898.21
B8: Konstruksi | C8: 11193.38 | D8: 11732.07 | E8: 12713.05 | F8: 13717.54 | G8: 51944.23 | H8: 52700.7 | I8: 55803.68 | J8: 59089.91 | K8: 211217.76 | L8: 216505.24 | M8: 231632.64 | N8: 238914.21 | O8: 126184.39 | P8: 133549.61 | Q8: 143014.89 | R8: 150684.6 | S8: 108657.61 | T8: 115250.87 | U8: 124441.81 | V8: 132673.93 | W8: 162018.82 | X8: 170190.58 | Y8: 181960.11 | Z8: 190304.86 | AA8: =C8+G8+K8+O8+S8+W8 -> 671216.19 | AB8: =D8+H8+L8+P8+T8+X8 -> 699929.07 | AC8: =E8+I8+M8+Q8+U8+Y8 -> 749566.18 | AD8: =F8+J8+N8+R8+V8+Z8 -> 785385.05
B9: Perdagangan Besar dan Eceran; Reparasi Mobil dan Sepeda Motor | C9: 8779.73 | D9: 9159.47 | E9: 9521.98 | F9: 10024.25 | G9: 64030.67 | H9: 66574.78 | I9: 69454.87 | J9: 72655.41 | K9: 307754.12 | L9: 321661.05 | M9: 343770.7 | N9: 362681.18 | O9: 230532.56 | P9: 240583.84 | Q9: 252244.61 | R9: 264862.53 | S9: 153670.44 | T9: 161240.41 | U9: 167931.17 | V9: 175700.39 | W9: 333626.69 | X9: 352837.67 | Y9: 368875.69 | Z9: 383580.62 | AA9: =C9+G9+K9+O9+S9+W9 -> 1098394.2 | AB9: =D9+H9+L9+P9+T9+X9 -> 1152057.2 | AC9: =E9+I9+M9+Q9+U9+Y9 -> 1211799 | AD9: =F9+J9+N9+R9+V9+Z9 -> 1269504.4
B10: Transportasi dan Pergudangan | C10: 5287.74 | D10: 5822.82 | E10: 6186.17 | F10: 6530.34 | G10: 27947.76 | H10: 31433.2 | I10: 33428.91 | J10: 34833.14 | K10: 74214.76 | L10: 84642.25 | M10: 90533.4 | N10: 98400.67 | O10: 75521.57 | P10: 83777.21 | Q10: 94113.89 | R10: 104938.19 | S10: 42103.03 | T10: 45523.39 | U10: 48052.76 | V10: 51285.06 | W10: 53240.33 | X10: 60314.16 | Y10: 66044.82 | Z10: 70889.1 | AA10: =C10+G10+K10+O10+S10+W10 -> 278315.19 | AB10: =D10+H10+L10+P10+T10+X10 -> 311513.03 | AC10: =E10+I10+M10+Q10+U10+Y10 -> 338359.95 | AD10: =F10+J10+N10+R10+V10+Z10 -> 366876.5
B11: Penyediaan Akomodasi dan Makan Minum | C11: 10259.81 | D11: 11173.46 | E11: 12131.02 | F11: 12899.6 | G11: 12249.58 | H11: 13284.07 | I11: 14221.36 | J11: 15157.59 | K11: 91152.68 | L11: 99983.06 | M11: 108295.65 | N11: 118398.38 | O11: 42972.84 | P11: 46721.89 | Q11: 49724.89 | R11: 54866.88 | S11: 38132.45 | T11: 42417.2 | U11: 46670.27 | V11: 51617.3 | W11: 9452.21 | X11: 101732.19 | Y11: 108833.45 | Z11: 117602.95 | AA11: =C11+G11+K11+O11+S11+W11 -> 204219.57 | AB11: =D11+H11+L11+P11+T11+X11 -> 315311.87 | AC11: =E11+I11+M11+Q11+U11+Y11 -> 339876.64 | AD11: =F11+J11+N11+R11+V11+Z11 -> 370542.7
B12: Informasi dan Komunikasi | C12: 16907.39 | D12: 17631.3 | E12: 18396.74 | F12: 19195.07 | G12: 33161.9 | H12: 35734.64 | I12: 37823.43 | J12: 39950.35 | K12: 262247.28 | L12: 281781.27 | M12: 295297.83 | N12: 313673.07 | O12: 97480.64 | P12: 105146 | Q12: 113765.59 | R12: 124147.98 | S12: 63846.51 | T12: 70658.78 | U12: 77416.08 | V12: 84182.23 | W12: 119126.09 | X12: 126994.5 | Y12: 135158.83 | Z12: 145374.43 | AA12: =C12+G12+K12+O12+S12+W12 -> 592769.81 | AB12: =D12+H12+L12+P12+T12+X12 -> 637946.49 | AC12: =E12+I12+M12+Q12+U12+Y12 -> 677858.5 | AD12: =F12+J12+N12+R12+V12+Z12 -> 726523.13
B13: Jasa Keuangan dan Asuransi | C13: 4018.73 | D13: 4432.25 | E13: 4721.39 | F13: 4794.84 | G13: 14912.11 | H13: 14810 | I13: 14850.57 | J13: 14594.36 | K13: 210508.45 | L13: 221857.65 | M13: 233740.3 | N13: 242701.8 | O13: 38743.11 | P13: 40184.13 | Q13: 41870.17 | R13: 43238.82 | S13: 27690.76 | T13: 28289.1 | U13: 28899.58 | V13: 30519.47 | W13: 43096.15 | X13: 44731.09 | Y13: 46473.15 | Z13: 47512.44 | AA13: =C13+G13+K13+O13+S13+W13 -> 338969.31 | AB13: =D13+H13+L13+P13+T13+X13 -> 354304.22 | AC13: =E13+I13+M13+Q13+U13+Y13 -> 370555.16 | AD13: =F13+J13+N13+R13+V13+Z13 -> 383361.73
B14: Real Estate | C14: 7864.69 | D14: 8155.53 | E14: 8487.82 | F14: 8831.62 | G14: 44509.24 | H14: 46071.63 | I14: 47716.22 | J14: 50549.62 | K14: 122960.43 | L14: 123874.01 | M14: 125748.53 | N14: 129233.11 | O14: 22993.05 | P14: 24426.12 | Q14: 26046.99 | R14: 28187.87 | S14: 20107.1 | T14: 21494.52 | U14: 22764.06 | V14: 24042.7 | W14: 31618.65 | X14: 32469.01 | Y14: 33414.39 | Z14: 34538.09 | AA14: =C14+G14+K14+O14+S14+W14 -> 250053.16 | AB14: =D14+H14+L14+P14+T14+X14 -> 256490.82 | AC14: =E14+I14+M14+Q14+U14+Y14 -> 264178.01 | AD14: =F14+J14+N14+R14+V14+Z14 -> 275383.01
... B19: Jasa Lainnya | C19: 3412.77 | D19: 3652.74 | E19: 3775.49 | F19: 4048.02 | G19: 7198 | H19: 7873.42 | I19: 8270.15 | J19: 8731.87 | K19: 78134.58 | L19: 87201.78 | M19: 91930.32 | N19: 99711.9 | O19: 35559.49 | P19: 38253.41 | Q19: 41286.15 | R19: 44975.22 | S19: 17963.16 | T19: 19294.49 | U19: 20609.68 | V19: 22288.53 | W19: 24250.11 | X19: 26492.18 | Y19: 28759.88 | Z19: 31037.36 | AA19: =C19+G19+K19+O19+S19+W19 -> 166518.11 | AB19: =D19+H19+L19+P19+T19+X19 -> 182768.02 | AC19: =E19+I19+M19+Q19+U19+Y19 -> 194631.67 | AD19: =F19+J19+N19+R19+V19+Z19 -> 210792.9
B20: TOTAL | C20: =SUM(C3:C19) -> 112901.34 | D20: =SUM(D3:D19) -> 118625.55 | E20: =SUM(E3:E19) -> 124590.44 | F20: =SUM(F3:F19) -> 131435.93 | G20: =SUM(G3:G19) -> 484131.21 | H20: =SUM(H3:H19) -> 507425.74 | I20: =SUM(I3:I19) -> 531735.24 | J20: =SUM(J3:J19) -> 560270.88 | ... P20: =SUM(P3:P19) -> 1669416.9 | Q20: 1752124.2 | R20: =SUM(R3:R19) -> 1845316.7 | S20: =SUM(S3:S19) -> 1050278.1 | T20: =SUM(T3:T19) -> 1102437.5 | U20: =SUM(U3:U19) -> 1156998.9 | V20: =SUM(V3:V19) -> 1219148.6 | W20: =SUM(W3:W19) -> 1673174.9 | X20: =SUM(X3:X19) -> 1844808.7 | Y20: =SUM(Y3:Y19) -> 1935810.1 | ... AD20: =SUM(AD3:AD19) -> 8058370.8
A24: No Sektor | B24: LQ ADHK | C24: DIY | G24: JAWA | K24: LQ
C25: 2022 | D25: 2023 | E25: 2024 | F25: 2025 | G25: 2022 | H25: 2023 | I25: 2024 | J25: 2025 | K25: 2022 | L25: 2023 | M25: 2024 | N25: 2025
A26: 1 | B26: Pertanian. Kehutanan. dan Perikanan | C26: =C3/C$20 -> 0.080404537 | D26: =D3/D$20 -> 0.07750472 | E26: =E3/E$20 -> 0.073894032 | F26: =F3/F$20 -> 0.074498883 | G26: =AA3/AA$20 -> 0.066253499 | H26: =AA3/AA$20 -> 0.066253499 | I26: =AC3/AC$20 -> 0.060570452 | J26: =AD3/AD$20 -> 0.061241826 | K26: =C26/G26 -> 1.2135893 | L26: =D26/H26 -> 1.1698208 | M26: =E26/I26 -> 1.2199683 | N26: =F26/J26 -> 1.2164706
A27: =1+A26 -> 2 | B27: Pertambangan dan Penggalian | C27: =C4/C$20 -> 0.0044377684 | D27: =D4/D$20 -> 0.0043610335 | E27: =E4/E$20 -> 0.0044738585 | F27: =F4/F$20 -> 0.0045038674 | G27: =AA4/AA$20 -> 0.017744569 | H27: =AA4/AA$20 -> 0.017744569 | I27: =AC4/AC$20 -> 0.016009974 | J27: =AD4/AD$20 -> 0.015370582 | K27: =C27/G27 -> 0.25009165 | L27: =D27/H27 -> 0.24576723 | M27: =E27/I27 -> 0.27944195 | N27: =F27/J27 -> 0.29301866
A28: =1+A27 -> 3 | B28: Industri Pengolahan | C28: =C5/C$20 -> 0.11417393 | D28: =D5/D$20 -> 0.11330822 | E28: =E5/E$20 -> 0.1119691 | F28: =F5/F$20 -> 0.11077496 | G28: =AA5/AA$20 -> 0.28674878 | H28: =AA5/AA$20 -> 0.28674878 | I28: =AC5/AC$20 -> 0.27854001 | J28: =AD5/AD$20 -> 0.27511815 | K28: =C28/G28 -> 0.3981671 | L28: =D28/H28 -> 0.39514804 | M28: =E28/I28 -> 0.40198571 | N28: =F28/J28 -> 0.40264505
A29: =1+A28 -> 4 | B29: Pengadaan Listrik dan Gas | C29: =C6/C$20 -> 0.0015785464 | D29: =D6/D$20 -> 0.0016123002 | E29: =E6/E$20 -> 0.0016989265 | F29: =F6/F$20 -> 0.0016838622 | G29: =AA6/AA$20 -> 0.0030889518 | H29: =AA6/AA$20 -> 0.0030889518 | I29: =AC6/AC$20 -> 0.0028236934 | J29: =AD6/AD$20 -> 0.0027048668 | K29: =C29/G29 -> 0.51102978 | L29: =D29/H29 -> 0.52195706 | M29: =E29/I29 -> 0.60166818 | N29: =F29/J29 -> 0.62253055
A30: =1+A29 -> 5 | B30: Pengadaan Air. Pengelolaan Sampah. Limbah dan Daur Ulang | C30: =C7/C$20 -> 0.0010153998 | D30: =D7/D$20 -> 0.00099953172 | E30: =E7/E$20 -> 0.00096010577 | F30: =F7/F$20 -> 0.00090507976 | G30: =AA7/AA$20 -> 0.00078886684 | H30: =AA7/AA$20 -> 0.00078886684 | I30: =AC7/AC$20 -> 0.00075587076 | J30: =AD7/AD$20 -> 0.00073193579 | K30: =C30/G30 -> 1.2871625 | L30: =D30/H30 -> 1.2670474 | M30: =E30/I30 -> 1.2701983 | N30: =F30/J30 -> 1.2365562
A31: =1+A30 -> 6 | B31: Konstruksi | C31: =C8/C$20 -> 0.099143022 | D31: =D8/D$20 -> 0.098900026 | E31: =E8/E$20 -> 0.10203873 | F31: =F8/F$20 -> 0.10436674 | G31: =AA8/AA$20 -> 0.097788485 | H31: =AA8/AA$20 -> 0.097788485 | I31: =AC8/AC$20 -> 0.097953054 | J31: =AD8/AD$20 -> 0.097462014 | K31: =C31/G31 -> 1.0138517 | L31: =D31/H31 -> 1.0113668 | M31: =E31/I31 -> 1.0417105 | N31: =F31/J31 -> 1.0708453
A32: =1+A31 -> 7 | B32: Perdagangan Besar dan Eceran; Reparasi Mobil dan Sepeda Motor | C32: =C9/C$20 -> 0.077764622 | D32: =D9/D$20 -> 0.077213298 | E32: =E9/E$20 -> 0.076426249 | F32: =F9/F$20 -> 0.076267197 | G32: =AA9/AA$20 -> 0.16002341 | H32: =AA9/AA$20 -> 0.16002341 | I32: =AC9/AC$20 -> 0.15835749 | J32: =AD9/AD$20 -> 0.15753859 | K32: =C32/G32 -> 0.48595778 | L32: =D32/H32 -> 0.48251251 | M32: =E32/I32 -> 0.48261848 | N32: =F32/J32 -> 0.48411756
A33: =1+A32 -> 8 | B33: Transportasi dan Pergudangan | C33: =C10/C$20 -> 0.046835051 | D33: =D10/D$20 -> 0.049085716 | E33: =E10/E$20 -> 0.049652044 | F33: =F10/F$20 -> 0.049684588 | G33: =AA10/AA$20 -> 0.040547325 | H33: =AA10/AA$20 -> 0.040547325 | I33: =AC10/AC$20 -> 0.044216764 | J33: =AD10/AD$20 -> 0.045527379 | K33: =C33/G33 -> 1.1550713 | L33: =D33/H33 -> 1.2105784 | M33: =E33/I33 -> 1.1229235 | N33: =F33/J33 -> 1.0913123
A34: =1+A33 -> 9 | B34: Penyediaan Akomodasi dan Makan Minum | C34: =C11/C$20 -> 0.090874121 | D34: =D11/D$20 -> 0.094191007 | E34: =E11/E$20 -> 0.097367182 | F34: =F11/F$20 -> 0.098143635 | G34: =AA11/AA$20 -> 0.029752444 | H34: =AA11/AA$20 -> 0.029752444 | I34: =AC11/AC$20 -> 0.044414964 | J34: =AD11/AD$20 -> 0.045982334 | K34: =C34/G34 -> 3.0543413 | L34: =D34/H34 -> 3.1658242 | M34: =E34/I34 -> 2.1922157 | N34: =F34/J34 -> 2.134377
A35: =1+A34 -> 10 | B35: Informasi dan Komunikasi | C35: =C12/C$20 -> 0.14975367 | D35: =D12/D$20 -> 0.14862987 | E35: =E12/E$20 -> 0.14765772 | F35: =F12/F$20 -> 0.14604127 | G35: =AA12/AA$20 -> 0.086359749 | H35: =AA12/AA$20 -> 0.086359749 | I35: =AC12/AC$20 -> 0.088582319 | J35: =AD12/AD$20 -> 0.09015757 | K35: =C35/G35 -> 1.7340679 | L35: =D35/H35 -> 1.7210549 | M35: =E35/I35 -> 1.6668983 | N35: =F35/J35 -> 1.6198448
A36: =1+A35 -> 11 | B36: Jasa Keuangan dan Asuransi | C36: =C13/C$20 -> 0.03559506 | D36: =D13/D$20 -> 0.037363367 | E36: =E13/E$20 -> 0.037895283 | F36: =F13/F$20 -> 0.036480436 | G36: =AA13/AA$20 -> 0.049383933 | H36: =AA13/AA$20 -> 0.049383933 | I36: =AC13/AC$20 -> 0.048424023 | J36: =AD13/AD$20 -> 0.047573106 | K36: =C36/G36 -> 0.72078221 | L36: =D36/H36 -> 0.75658955 | M36: =E36/I36 -> 0.78257198 | N36: =F36/J36 -> 0.76682897
A37: =1+A36 -> 12 | B37: Real Estate | C37: =C14/C$20 -> 0.069659846 | D37: =D14/D$20 -> 0.068750198 | E37: =E14/E$20 -> 0.068125773 | F37: =F14/F$20 -> 0.067193347 | G37: =AA14/AA$20 -> 0.036429872 | H37: =AA14/AA$20 -> 0.036429872 | I37: =AC14/AC$20 -> 0.034522693 | J37: =AD14/AD$20 -> 0.034173534 | K37: =C37/G37 -> 1.9121628 | L37: =D37/H37 -> 1.887193 | M37: =E37/I37 -> 1.9733621 | N37: =F37/J37 -> 1.9662393
A38: =1+A37 -> 13 | B38: Jasa Perusahaan | C38: =C15/C$20 -> 0.010690307 | D38: =D15/D$20 -> 0.010999907 | E38: =E15/E$20 -> 0.011074847 | F38: =F15/F$20 -> 0.010965419 | G38: =AA15/AA$20 -> 0.027761579 | H38: =AA15/AA$20 -> 0.027761579 | I38: =AC15/AC$20 -> 0.027894768 | J38: =AD15/AD$20 -> 0.028550077 | K38: =C38/G38 -> 0.38507562 | L38: =D38/H38 -> 0.39622771 | M38: =E38/I38 -> 0.39702235 | N38: =F38/J38 -> 0.38407667
... A42: =1+A41 -> 17 | B42: Jasa Lainnya | C42: =C19/C$20 -> 0.030227896 | D42: =D19/D$20 -> 0.030792186 | E42: =E19/E$20 -> 0.030303208 | F42: =F19/F$20 -> 0.030798428 | G42: =AA19/AA$20 -> 0.024259775 | H42: =AA19/AA$20 -> 0.024259775 | I42: =AC19/AC$20 -> 0.025434401 | J42: =AD19/AD$20 -> 0.026158253 | K42: =C42/G42 -> 1.2460089 | L42: =D42/H42 -> 1.2692692 | M42: =E42/I42 -> 1.1914261 | N42: =F42/J42 -> 1.1773886
B43: TOTAL | C43: =SUM(C26:C42) -> 1 | D43: =SUM(D26:D42) -> 1 | E43: =SUM(E26:E42) -> 1 | F43: =SUM(F26:F42) -> 1 | G43: =SUM(G26:G42) -> 1 | H43: =SUM(H26:H42) -> 1 | I43: =SUM(I26:I42) -> 1 | J43: =SUM(J26:J42) -> 1 | K43: =C43/G43 -> 1 | L43: =D43/H43 -> 1 | M43: =E43/I43 -> 1 | N43: =F43/J43 -> 1
B46: LQ > 1: Sektor Basis (Unggulan), memiliki keunggulan komparatif dan mampu mengekspor. | C46: 122
B47: LQ < 1: Sektor Non-Basis, belum mampu memenuhi kebutuhan sendiri dan impor.
B48: LQ = 1: Sektor Netral, kebutuhan sektor setara dengan rata-rata wilayah acuan.

Sheet LQ ADHB
A1: Satuan Milyar rupiah | B1: DIY | F1: Banten | J1: DKI Jakarta | N1: Jawa Barat | R1: Jawa Tengah | V1: Jawa Timur | Z1: TOTAL JAWA
B2: 2022 | C2: 2023 | D2: 2024 | E2: 2025 | F2: 2022 | G2: 2023 | H2: 2024 | I2: 2025 | J2: 2022 | K2: 2023 | L2: 2024 | M2: 2025** | N2: 2022 | O2: 2023 | P2: 2024 | Q2: 2025*** | R2: 2022 | S2: 2023 | T2: 2024 | U2: 2025 | V2: 2022 | W2: 2023 | X2: 2024 | Y2: 2025 | Z2: 2022 | AA2: 2023 | AB2: 2024 | AC2: 2025
A3: Pertanian. Kehutanan. dan Perikanan | B3: 16525.78 | C3: 18541.32 | D3: 19266.67 | E3: 21082.58 | F3: 44050.68 | G3: 46608.45 | H3: 49367.5 | I3: 55984.25 | J3: 2530.73 | K3: 2516.65 | L3: 2762.53 | M3: 2762.53 | N3: 207716.66 | O3: 221650.61 | P3: 237631.6 | Q3: 267710.3 | R3: 211490.54 | S3: 224291.41 | T3: 237348.86 | U3: 253907.09 | V3: 303510.39 | W3: 326087.35 | X3: 337697.52 | Y3: 365375.14 | Z3: =SUM(B3,F3,J3,N3,R3,V3) -> 785824.78 | AA3: =SUM(C3,G3,K3,O3,S3,W3) -> 839695.79 | AB3: =SUM(D3,H3,L3,P3,T3,X3) -> 884074.68 | AC3: =SUM(E3,I3,M3,Q3,U3,Y3) -> 966821.89
A4: Pertambangan dan Penggalian | B4: 713.77 | C4: 799.92 | D4: 871.35 | E4: 791.27 | F4: 4142.46 | G4: 3504.21 | H4: 3321.9 | I4: 3441.02 | J4: 8031.15 | K4: 6005.63 | L4: 5717.42 | M4: 5717.42 | N4: 27934.5 | O4: 26089.3 | P4: 27360.32 | Q4: 27600.49 | R4: 37723.92 | S4: 38102.94 | T4: 39211.8 | U4: 40556.56 | V4: 119698.47 | W4: 112701.63 | X4: 113344.46 | Y4: 113099.01 | Z4: =SUM(B4,F4,J4,N4,R4,V4) -> 198244.27 | AA4: =SUM(C4,G4,K4,O4,S4,W4) -> 187203.63 | AB4: =SUM(D4,H4,L4,P4,T4,X4) -> 189827.25 | AC4: =SUM(E4,I4,M4,Q4,U4,Y4) -> 191205.77
A5: Industri Pengolahan | B5: 19775.46 | C5: 21352.59 | D5: 22927.55 | E5: 24552.34 | F5: 227665.58 | G5: 246265.69 | H5: 265140.7 | I5: 285314.72 | J5: 391219.26 | K5: 408799.84 | L5: 422940.32 | M5: 422940.32 | N5: 1023400.8 | O5: 1099081.2 | P5: 1168548.2 | Q5: 1227809 | R5: 529181.82 | S5: 576208.65 | T5: 614658.98 | U5: 648749.29 | V5: 835393.31 | W5: 901185.69 | X5: 977507.54 | Y5: 1065685.8 | Z5: =SUM(B5,F5,J5,N5,R5,V5) -> 3026636.2 | AA5: =SUM(C5,G5,K5,O5,S5,W5) -> 3252893.7 | AB5: =SUM(D5,H5,L5,P5,T5,X5) -> 3471723.3 | AC5: =SUM(E5,I5,M5,Q5,U5,Y5) -> 3675051.5
A6: Pengadaan Listrik dan Gas | B6: 223.58 | C6: 250 | D6: 277.56 | E6: 292.22 | F6: 13017.8 | G6: 12785.13 | H6: 10831.56 | I6: 11372.92 | J6: 7486.94 | K6: 6878.99 | L6: 5628.35 | M6: 5628.35 | N6: 12161.53 | O6: 12221.17 | P6: 12059.32 | Q6: 12551.2 | R6: 1438 | S6: 1556.85 | T6: 1675.83 | U6: 1752.77 | V6: 8042.88 | W6: 10374.52 | X6: 11181.77 | Y6: 11981.83 | Z6: =SUM(B6,F6,J6,N6,R6,V6) -> 42370.73 | AA6: =SUM(C6,G6,K6,O6,S6,W6) -> 44066.66 | AB6: =SUM(D6,H6,L6,P6,T6,X6) -> 41654.39 | AC6: =SUM(E6,I6,M6,Q6,U6,Y6) -> 43579.29
A7: Pengadaan Air. Pengelolaan Sampah. Limbah dan Daur Ulang | B7: 162.57 | C7: 171.98 | D7: 174.22 | E7: 174.28 | F7: 612.68 | G7: 652.28 | H7: 718.35 | I7: 769.82 | J7: 984.18 | K7: 1057.43 | L7: 1121.37 | M7: 1121.37 | N7: 2485.54 | O7: 2575.78 | P7: 2872.12 | Q7: 3044.19 | R7: 938.29 | S7: 985.79 | T7: 1066.34 | U7: 1123.96 | V7: 2443.2 | W7: 2541.86 | X7: 2626.96 | Y7: 2763.35 | Z7: =SUM(B7,F7,J7,N7,R7,V7) -> 7626.46 | AA7: =SUM(C7,G7,K7,O7,S7,W7) -> 7985.12 | AB7: =SUM(D7,H7,L7,P7,T7,X7) -> 8579.36 | AC7: =SUM(E7,I7,M7,Q7,U7,Y7) -> 8996.97
A8: Konstruksi | B8: 16440.15 | C8: 17036.95 | D8: 18627.62 | E8: 20420.61 | F8: 91184.67 | G8: 95666.94 | H8: 102165.15 | I8: 110523.6 | J8: 351920.99 | K8: 372447.93 | L8: 401305.8 | M8: 401305.8 | N8: 202276.62 | O8: 221150.71 | P8: 238500.79 | Q8: 253691.2 | R8: 172199.81 | S8: 190384.35 | T8: 207039.33 | U8: 222900.55 | V8: 246876.37 | W8: 263243.87 | X8: 284121.28 | Y8: 299579.06 | Z8: =SUM(B8,F8,J8,N8,R8,V8) -> 1080898.6 | AA8: =SUM(C8,G8,K8,O8,S8,W8) -> 1159930.8 | AB8: =SUM(D8,H8,L8,P8,T8,X8) -> 1251760 | AC8: =SUM(E8,I8,M8,Q8,U8,Y8) -> 1308420.8
A9: Perdagangan Besar dan Eceran; Reparasi Mobil dan Sepeda Motor | B9: 13677.56 | C9: 14768.7 | D9: 15623.23 | E9: 16761.57 | F9: 93547.29 | G9: 101006.64 | H9: 108163.85 | I9: 115667.09 | J9: 555567.92 | K9: 608311.63 | L9: 662471.32 | M9: 662471.32 | N9: 348996.55 | O9: 378832.69 | P9: 408257.19 | Q9: 438021.6 | R9: 212208.01 | S9: 230723.26 | T9: 245140.47 | U9: 262081.27 | V9: 509889.56 | W9: 558385.86 | X9: 596083.66 | Y9: 631235.53 | Z9: =SUM(B9,F9,J9,N9,R9,V9) -> 1733886.9 | AA9: =SUM(C9,G9,K9,O9,S9,W9) -> 1892028.8 | AB9: =SUM(D9,H9,L9,P9,T9,X9) -> 2035739.7 | AC9: =SUM(E9,I9,M9,Q9,U9,Y9) -> 2126238.4
A10: Transportasi dan Pergudangan | B10: 8483.54 | C10: 10135.39 | D10: 11282.92 | E10: 11933.75 | F10: 71161.82 | G10: 90542.7 | H10: 100200.91 | I10: 103587.51 | J10: 126971.27 | K10: 151850.8 | L10: 166936.1 | M10: 166936.1 | N10: 130202.05 | O10: 155099.82 | P10: 176286.29 | Q10: 200138.9 | R10: 59256.75 | S10: 69538.67 | T10: 74443.94 | U10: 80201.66 | V10: 96434.87 | W10: 119171.36 | X10: 132252.92 | Y10: 142333.91 | Z10: =SUM(B10,F10,J10,N10,R10,V10) -> 492510.3 | AA10: =SUM(C10,G10,K10,O10,S10,W10) -> 596338.74 | AB10: =SUM(D10,H10,L10,P10,T10,X10) -> 661403.08 | AC10: =SUM(E10,I10,M10,Q10,U10,Y10) -> 705131.83
A11: Penyediaan Akomodasi dan Makan Minum | B11: 16374.44 | C11: 18421.95 | D11: 20534.52 | E11: 22713.47 | F11: 17447.46 | G11: 19150.09 | H11: 21071.86 | I11: 22828.46 | J11: 143663.36 | K11: 161237.93 | L11: 178510.88 | M11: 178510.88 | N11: 69670.16 | O11: 79501.42 | P11: 86660.1 | Q11: 97413.82 | R11: 51316.31 | S11: 57757.14 | T11: 64731.32 | U11: 72617.6 | V11: 154142.37 | W11: 173189.33 | X11: 189716.7 | Y11: 208494.46 | Z11: =SUM(B11,F11,J11,N11,R11,V11) -> 452614.1 | AA11: =SUM(C11,G11,K11,O11,S11,W11) -> 509257.86 | AB11: =SUM(D11,H11,L11,P11,T11,X11) -> 561225.38 | AC11: =SUM(E11,I11,M11,Q11,U11,Y11) -> 602578.69
A12: Informasi dan Komunikasi | B12: 17073.16 | C12: 18110.08 | D12: 18931.12 | E12: 20056.23 | F12: 28218.24 | G12: 30601.82 | H12: 32734.19 | I12: 34663.22 | J12: 294865.58 | K12: 320987.64 | L12: 342477.64 | M12: 342477.64 | N12: 92644.33 | O12: 100002.58 | P12: 108134.62 | Q12: 117665 | R12: 62593.23 | S12: 69420.57 | T12: 76438.36 | U12: 83408.76 | V12: 135673.33 | W12: 145547.25 | X12: 156394.33 | Y12: 168566.56 | Z12: =SUM(B12,F12,J12,N12,R12,V12) -> 631067.87 | AA12: =SUM(C12,G12,K12,O12,S12,W12) -> 684669.94 | AB12: =SUM(D12,H12,L12,P12,T12,X12) -> 735110.26 | AC12: =SUM(E12,I12,M12,Q12,U12,Y12) -> 766837.41
A13: Jasa Keuangan dan Asuransi | B13: 6830.31 | C13: 7678.61 | D13: 8250.02 | E13: 8561.35 | F13: 25307.63 | G13: 25724.53 | H13: 26054.81 | I13: 25992.58 | J13: 352956.32 | K13: 382294.93 | L13: 408186.14 | M13: 408186.14 | N13: 69885.95 | O13: 74126.26 | P13: 78558.46 | Q13: 83737.81 | R13: 46920.61 | S13: 48965.2 | T13: 50560.09 | U13: 54552.68 | V13: 72592.53 | W13: 77073.8 | X13: 80978.2 | Y13: 84295.03 | Z13: =SUM(B13,F13,J13,N13,R13,V13) -> 574493.35 | AA13: =SUM(C13,G13,K13,O13,S13,W13) -> 615863.33 | AB13: =SUM(D13,H13,L13,P13,T13,X13) -> 652587.72 | AC13: =SUM(E13,I13,M13,Q13,U13,Y13) -> 665325.59
A14: Real Estate | B14: 11195.83 | C14: 11930.69 | D14: 12540.58 | E14: 13482.51 | F14: 60289.4 | G14: 64183.34 | H14: 67427.4 | I14: 73458.86 | J14: 186183.76 | K14: 193776 | L14: 200045.22 | M14: 200045.22 | N14: 28413.16 | O14: 30746.38 | P14: 32865.01 | Q14: 35902.46 | R14: 25420.79 | S14: 27455.79 | T14: 29153.89 | U14: 31091.49 | V14: 44748.26 | W14: 46496.44 | X14: 48278.29 | Y14: 51192.48 | Z14: =SUM(B14,F14,J14,N14,R14,V14) -> 356251.2 | AA14: =SUM(C14,G14,K14,O14,S14,W14) -> 374588.64 | AB14: =SUM(D14,H14,L14,P14,T14,X14) -> 390310.39 | AC14: =SUM(E14,I14,M14,Q14,U14,Y14) -> 405173.02
... A17: Jasa Pendidikan | B17: 13913.75 | C17: 15212.77 | D17: 16027.4 | E17: 17051 | F17: 24581.06 | G17: 26680.99 | H17: 29453.36 | I17: 31944.14 | J17: 149353.37 | K17: 150213.28 | L17: 159541.97 | M17: 159541.97 | N17: 80336.14 | O17: 86301.84 | P17: 92230.1 | Q17: 99553.07 | R17: 65985.53 | S17: 70550.28 | T17: 77978.57 | U17: 84860.79 | V17: 67704.93 | W17: 72543.67 | X17: 77115.59 | Y17: 83169.6 | Z17: =SUM(B17,F17,J17,N17,R17,V17) -> 401874.78 | AA17: =SUM(C17,G17,K17,O17,S17,W17) -> 421502.83 | AB17: =SUM(D17,H17,L17,P17,T17,X17) -> 452346.99 | AC17: =SUM(E17,I17,M17,Q17,U17,Y17) -> 476120.57
A18: Jasa Kesehatan dan Kegiatan Sosial | B18: 5131.07 | C18: 5789.17 | D18: 6253.69 | E18: 6789.31 | F18: 10687.98 | G18: 11.841.83 | H18: 13208.08 | I18: 13840.12 | J18: 70997.34 | K18: 76588.42 | L18: 82004.51 | M18: 82004.51 | N18: 19157.24 | O18: 20978.21 | P18: 22908.96 | Q18: 25573.7 | R18: 14372.31 | S18: 15533.75 | T18: 16932.97 | U18: 18109.07 | V18: 18875.47 | W18: 20154.16 | X18: 21473.36 | Y18: 23719.81 | Z18: =SUM(B18,F18,J18,N18,R18,V18) -> 139221.41 | AA18: =SUM(C18,G18,K18,O18,S18,W18) -> 139043.71 | AB18: =SUM(D18,H18,L18,P18,T18,X18) -> 162781.57 | AC18: =SUM(E18,I18,M18,Q18,U18,Y18) -> 170036.52
A19: Jasa Lainnya | B19: 4721.76 | C19: 5293.81 | D19: 5548.53 | E19: 6186.01 | F19: 12163.45 | G19: 13971.78 | H19: 14903.65 | I19: 16027.73 | J19: 128238.43 | K19: 149693.7 | L19: 159695.26 | M19: 159695.26 | N19: 52154.05 | O19: 58490.22 | P19: 66839.94 | Q19: 79766.91 | R19: 24413.4 | S19: 27022.68 | T19: 29586.58 | U19: 32949.35 | V19: 35552.39 | W19: 40663.65 | X19: 45132.22 | Y19: 51.099.95 | Z19: =SUM(B19,F19,J19,N19,R19,V19) -> 257243.48 | AA19: =SUM(C19,G19,K19,O19,S19,W19) -> 295135.84 | AB19: =SUM(D19,H19,L19,P19,T19,X19) -> 321706.18 | AC19: =SUM(E19,I19,M19,Q19,U19,Y19) -> 294625.26
A20: TOTAL | B20: =sum(B3:B19) -> 165724.52 | C20: =sum(C3:C19) -> 180746.4 | D20: =sum(D3:D19) -> 193561.95 | E20: =sum(E3:E19) -> 208133.81 | F20: =sum(F3:F19) -> 747223.58 | G20: =sum(G3:G19) -> 802282.49 | H20: =sum(H3:H19) -> 873626.26 | I20: =sum(I3:I19) -> 936203.97 | ... Y20: =sum(Y3:Y19) -> 3352066.9 | Z20: =SUM(B20,F20,J20,N20,R20,V20) -> 10814836 | AA20: =sum(AA3:AA19) -> 11700582 | AB20: =sum(AB3:AB19) -> 12556242 | AC20: =sum(AC3:AC19) -> 13157969
A24: LQ ADBH | B24: DIY | F24: JAWA | J24: LQ
B25: 2022 | C25: 2023 | D25: 2024 | E25: 2025 | F25: 2022 | G25: 2023 | H25: 2024 | I25: 2025 | J25: 2022 | K25: 2023 | L25: 2024 | M25: 2025
A26: Pertanian. Kehutanan. dan Perikanan | B26: =B3/B$20 -> 0.099718376 | C26: =C3/C$20 -> 0.10258196 | D26: =D3/D$20 -> 0.099537487 | E26: =E3/E$20 -> 0.10129339 | F26: =Z3/Z$20 -> 0.07266174 | G26: =Z3/Z$20 -> 0.07266174 | H26: =AB3/AB$20 -> 0.070409178 | I26: =AC3/AC$20 -> 0.073478048 | J26: =B26/F26 -> 1.3723643 | K26: =C26/G26 -> 1.4117741 | L26: =D26/H26 -> 1.4137005 | M26: =E26/I26 -> 1.3785531
A27: Pertambangan dan Penggalian | B27: =B4/B$20 -> 0.0043069668 | C27: =C4/C$20 -> 0.0044256483 | D27: =D4/D$20 -> 0.0045016595 | E27: =E4/E$20 -> 0.003801737 | F27: =Z4/Z$20 -> 0.01833077 | G27: =Z4/Z$20 -> 0.01833077 | H27: =AB4/AB$20 -> 0.015118158 | I27: =AC4/AC$20 -> 0.014531556 | J27: =B27/F27 -> 0.23495831 | K27: =C27/G27 -> 0.24143275 | L27: =D27/H27 -> 0.29776508 | M27: =E27/I27 -> 0.26161939
A28: Industri Pengolahan | B28: =B5/B$20 -> 0.1193273 | C28: =C5/C$20 -> 0.11813563 | D28: =D5/D$20 -> 0.11845071 | E28: =E5/E$20 -> 0.11796421 | F28: =Z5/Z$20 -> 0.27985966 | G28: =Z5/Z$20 -> 0.27985966 | H28: =AB5/AB$20 -> 0.27649382 | I28: =AC5/AC$20 -> 0.27930233 | J28: =B28/F28 -> 0.42638265 | K28: =C28/G28 -> 0.42212455 | L28: =D28/H28 -> 0.42840273 | M28: =E28/I28 -> 0.42235311
A29: Pengadaan Listrik dan Gas | B29: =B6/B$20 -> 0.0013491063 | C29: =C6/C$20 -> 0.0013831534 | D29: =D6/D$20 -> 0.0014339595 | E29: =E6/E$20 -> 0.0014040006 | F29: =Z6/Z$20 -> 0.0039178339 | G29: =Z6/Z$20 -> 0.0039178339 | H29: =AB6/AB$20 -> 0.0033174249 | I29: =AC6/AC$20 -> 0.0033120073 | J29: =B29/F29 -> 0.34435006 | K29: =C29/G29 -> 0.35304034 | L29: =D29/H29 -> 0.43225078 | M29: =E29/I29 -> 0.4239123
A30: Pengadaan Air. Pengelolaan Sampah. Limbah dan Daur Ulang | B30: =B7/B$20 -> 0.00098096528 | C30: =C7/C$20 -> 0.0009514989 | D30: =D7/D$20 -> 0.00090007359 | E30: =E7/E$20 -> 0.00083734594 | F30: =Z7/Z$20 -> 0.00070518501 | G30: =Z7/Z$20 -> 0.00070518501 | H30: =AB7/AB$20 -> 0.0006832745 | I30: =AC7/AC$20 -> 0.00068376585 | J30: =B30/F30 -> 1.3910751 | K30: =C30/G30 -> 1.3492897 | L30: =D30/H30 -> 1.3172943 | M30: =E30/I30 -> 1.2246092
A31: Konstruksi | B31: =B8/B$20 -> 0.099201675 | C31: =C8/C$20 -> 0.094258862 | D31: =D8/D$20 -> 0.09623596 | E31: =E8/E$20 -> 0.098112892 | F31: =Z8/Z$20 -> 0.099945912 | G31: =Z8/Z$20 -> 0.099945912 | H31: =AB8/AB$20 -> 0.099692246 | I31: =AC8/AC$20 -> 0.09943942 | J31: =B31/F31 -> 0.99255361 | K31: =C31/G31 -> 0.94309873 | L31: =D31/H31 -> 0.96533044 | M31: =E31/I31 -> 0.98665994
A32: Perdagangan Besar dan Eceran; Reparasi Mobil dan Sepeda Motor | B32: =B9/B$20 -> 0.082531903 | C32: =C9/C$20 -> 0.081709511 | D32: =D9/D$20 -> 0.080714366 | E32: =E9/E$20 -> 0.080532663 | F32: =Z9/Z$20 -> 0.16032485 | G32: =Z9/Z$20 -> 0.16032485 | H32: =AB9/AB$20 -> 0.1621297 | I32: =AC9/AC$20 -> 0.1615932 | J32: =B32/F32 -> 0.51477924 | K32: =C32/G32 -> 0.5096497 | L32: =D32/H32 -> 0.49783826 | M32: =E32/I32 -> 0.49836665
A33: Transportasi dan Pergudangan | B33: =B10/B$20 -> 0.051190614 | C33: =C10/C$20 -> 0.056075197 | D33: =D10/D$20 -> 0.058291002 | E33: =E10/E$20 -> 0.057336912 | F33: =Z10/Z$20 -> 0.045540248 | G33: =Z10/Z$20 -> 0.045540248 | H33: =AB10/AB$20 -> 0.052675241 | I33: =AC10/AC$20 -> 0.053589716 | J33: =B33/F33 -> 1.1240741 | K33: =C33/G33 -> 1.2313327 | L33: =D33/H33 -> 1.106611 | M33: =E33/I33 -> 1.0699238
A34: Penyediaan Akomodasi dan Makan Minum | B34: =B11/B$20 -> 0.098805174 | C34: =C11/C$20 -> 0.10192153 | D34: =D11/D$20 -> 0.10608759 | E34: =E11/E$20 -> 0.10912917 | F34: =Z11/Z$20 -> 0.041851223 | G34: =Z11/Z$20 -> 0.041851223 | H34: =AB11/AB$20 -> 0.044696923 | I34: =AC11/AC$20 -> 0.045795721 | J34: =B34/F34 -> 2.3608671 | K34: =C34/G34 -> 2.4353298 | L34: =D34/H34 -> 2.3734875 | M34: =E34/I34 -> 2.3829556
A35: Informasi dan Komunikasi | B35: =B12/B$20 -> 0.10302133 | C35: =C12/C$20 -> 0.10019608 | D35: =D12/D$20 -> 0.097803933 | E35: =E12/E$20 -> 0.096362191 | F35: =Z12/Z$20 -> 0.058352054 | G35: =Z12/Z$20 -> 0.058352054 | H35: =AB12/AB$20 -> 0.058545404 | I35: =AC12/AC$20 -> 0.058279314 | J35: =B35/F35 -> 1.7655133 | K35: =C35/G35 -> 1.717096 | L35: =D35/H35 -> 1.6705655 | M35: =E35/I35 -> 1.6534545
A36: Jasa Keuangan dan Asuransi | B36: =B13/B$20 -> 0.041214843 | C36: =C13/C$20 -> 0.042482783 | D36: =D13/D$20 -> 0.042622117 | E36: =E13/E$20 -> 0.041133874 | F36: =Z13/Z$20 -> 0.053120858 | G36: =Z13/Z$20 -> 0.053120858 | H36: =AB13/AB$20 -> 0.051973171 | I36: =AC13/AC$20 -> 0.050564459 | J36: =B36/F36 -> 0.77586929 | K36: =C36/G36 -> 0.79973826 | L36: =D36/H36 -> 0.8200792 | M36: =E36/I36 -> 0.81349381
A37: Real Estate | B37: =B14/B$20 -> 0.067556871 | C37: =C14/C$20 -> 0.066007898 | D37: =D14/D$20 -> 0.064788457 | E37: =E14/E$20 -> 0.064778087 | F37: =Z14/Z$20 -> 0.032940972 | G37: =Z14/Z$20 -> 0.032940972 | H37: =AB14/AB$20 -> 0.031084969 | I37: =AC14/AC$20 -> 0.030792975 | J37: =B37/F37 -> 2.0508463 | K37: =C37/G37 -> 2.0038236 | L37: =D37/H37 -> 2.0842375 | M37: =E37/I37 -> 2.1036644
... A42: Jasa Lainnya | B42: =B19/B$20 -> 0.02849162 | C42: =C19/C$20 -> 0.029288605 | D42: =D19/D$20 -> 0.028665396 | E42: =E19/E$20 -> 0.029721312 | F42: =Z19/Z$20 -> 0.023786166 | G42: =Z19/Z$20 -> 0.023786166 | H42: =AB19/AB$20 -> 0.025621215 | I42: =AC19/AC$20 -> 0.022391393 | J42: =B42/F42 -> 1.1978231 | K42: =C42/G42 -> 1.2313294 | L42: =D42/H42 -> 1.1188149 | M42: =E42/I42 -> 1.3273543
A43: TOTAL | B43: =SUM(B26:B42) -> 1 | C43: =SUM(C26:C42) -> 1 | D43: =SUM(D26:D42) -> 1 | E43: =SUM(E26:E42) -> 1 | F43: =SUM(F26:F42) -> 1 | G43: =SUM(G26:G42) -> 1 | H43: =SUM(H26:H42) -> 1 | I43: =SUM(I26:I42) -> 1 | J43: =B43/F43 -> 1 | K43: =C43/G43 -> 1 | L43: =D43/H43 -> 1 | M43: =E43/I43 -> 1
A46: LQ > 1: Sektor Basis (Unggulan), memiliki keunggulan komparatif dan mampu mengekspor.
A47: LQ < 1: Sektor Non-Basis, belum mampu memenuhi kebutuhan sendiri dan impor.
A48: LQ = 1: Sektor Netral, kebutuhan sektor setara dengan rata-rata wilayah acuan.

Sheet Tipologi Klassen ADHK
A1: Satuan Milyar rupiah | B1: DIY | F1: Banten | J1: DKI Jakarta | N1: Jawa Barat | R1: Jawa Tengah | V1: Jawa Timur | Z1: TOTAL JAWA
B2: 2022 | C2: 2023 | D2: 2024 | E2: 2025 | F2: 2022 | G2: 2023 | H2: 2024 | I2: 2025 | J2: 2022 | K2: 2023 | L2: 2024 | M2: 2025** | N2: 2022 | O2: 2023 | P2: 2024 | Q2: 2025*** | R2: 2022 | S2: 2023 | T2: 2024 | U2: 2025 | V2: 2022 | W2: 2023 | X2: 2024 | Y2: 2025 | Z2: 2022 | AA2: 2023 | AB2: 2024 | AC2: 2025
A3: Pertanian. Kehutanan. dan Perikanan | B3: 9077.78 | C3: 9194.04 | D3: 9206.49 | E3: 9791.83 | F3: 26485.81 | G3: 26532.32 | H3: 26703.4 | I3: 29266.23 | J3: 1501.26 | K3: 1442.05 | L3: 1516.6 | M3: 1561.67 | N3: 113186.4 | O3: 113308.53 | P3: 115104.77 | Q3: 126696.5 | R3: 130762.52 | S3: 131330.54 | T3: 133162.54 | U3: 139530.4 | V3: 173747.56 | W3: 177668.37 | X3: 177809.48 | Y3: 186662.71 | Z3: =B3+F3+J3+N3+R3+V3 -> 454761.33 | AA3: =C3+G3+K3+O3+S3+W3 -> 459475.85 | AB3: =D3+H3+L3+P3+T3+X3 -> 463503.28 | AC3: =E3+I3+M3+Q3+U3+Y3 -> 493509.34
A4: Pertambangan dan Penggalian | B4: 501.03 | C4: 517.33 | D4: 557.4 | E4: 591.97 | F4: 2208.48 | G4: 1844.63 | H4: 1713.75 | I4: 1728.33 | J4: 2400.31 | K4: 2094.15 | L4: 1983.75 | M4: 1830.18 | N4: 23880.32 | O4: 23857.09 | P4: 23842.6 | Q4: 23723.09 | R4: 20942.66 | S4: 21232.09 | T4: 21833.06 | U4: 22315.21 | V4: 71865.2 | W4: 73057.78 | X4: 72582.57 | Y4: 73673.07 | Z4: =B4+F4+J4+N4+R4+V4 -> 121798 | AA4: =C4+G4+K4+O4+S4+W4 -> 122603.07 | AB4: =D4+H4+L4+P4+T4+X4 -> 122513.13 | AC4: =E4+I4+M4+Q4+U4+Y4 -> 123861.85
A5: Industri Pengolahan | B5: 12890.39 | C5: 13441.25 | D5: 13950.28 | E5: 14559.81 | F5: 160616.13 | G5: 169934.05 | H5: 178397.5 | I5: 187979.82 | J5: 228741.59 | K5: 232991.97 | L5: 235646 | M5: 239531.41 | N5: 683420.22 | O5: 715806.62 | P5: 741041.45 | Q5: 762103.15 | R5: 346169.65 | S5: 361111.03 | T5: 373837.72 | U5: 389026.51 | V5: 536394.03 | W5: 558448.65 | X5: 588598.82 | Y5: 623803.37 | Z5: =B5+F5+J5+N5+R5+V5 -> 1968232 | AA5: =C5+G5+K5+O5+S5+W5 -> 2051733.6 | AB5: =D5+H5+L5+P5+T5+X5 -> 2131471.8 | AC5: =E5+I5+M5+Q5+U5+Y5 -> 2217004.1
A6: Pengadaan Listrik dan Gas | B6: 178.22 | C6: 191.26 | D6: 211.67 | E6: 221.32 | F6: 4639.58 | G6: 4571.07 | H6: 4156.25 | I6: 4248.46 | J6: 4261.4 | K6: 3961.69 | L6: 3315.23 | M6: 2901.2 | N6: 5843.37 | O6: 5854.08 | P6: 5818.98 | Q6: 5916.01 | R6: 1214.86 | S6: 1297.42 | T6: 1387.68 | U6: 1448.95 | V6: 5065.01 | W6: 6282.63 | X6: 6717.94 | Y6: 7060.88 | Z6: =B6+F6+J6+N6+R6+V6 -> 21202.44 | AA6: =C6+G6+K6+O6+S6+W6 -> 22158.15 | AB6: =D6+H6+L6+P6+T6+X6 -> 21607.75 | AC6: =E6+I6+M6+Q6+U6+Y6 -> 21796.82
A7: Pengadaan Air. Pengelolaan Sampah. Limbah dan Daur Ulang | B7: 114.64 | C7: 118.57 | D7: 119.62 | E7: 118.96 | F7: 512.65 | G7: 540.27 | H7: 561.21 | I7: 585.9 | J7: 777.42 | K7: 826.6 | L7: 830.59 | M7: 800.67 | N7: 1456.85 | O7: 1495.07 | P7: 1577.05 | Q7: 1618.71 | R7: 752.41 | S7: 783.02 | T7: 800.9 | U7: 811.85 | V7: 1800.78 | W7: 1853.34 | X7: 1894.78 | Y7: 1962.12 | Z7: =B7+F7+J7+N7+R7+V7 -> 5414.75 | AA7: =C7+G7+K7+O7+S7+W7 -> 5616.87 | AB7: =D7+H7+L7+P7+T7+X7 -> 5784.15 | AC7: =E7+I7+M7+Q7+U7+Y7 -> 5898.21
A8: Konstruksi | B8: 11193.38 | C8: 11732.07 | D8: 12713.05 | E8: 13717.54 | F8: 51944.23 | G8: 52700.7 | H8: 55803.68 | I8: 59089.91 | J8: 211217.76 | K8: 216505.24 | L8: 231632.64 | M8: 238914.21 | N8: 126184.39 | O8: 133549.61 | P8: 143014.89 | Q8: 150684.6 | R8: 108657.61 | S8: 115250.87 | T8: 124441.81 | U8: 132673.93 | V8: 162018.82 | W8: 170190.58 | X8: 181960.11 | Y8: 190304.86 | Z8: =B8+F8+J8+N8+R8+V8 -> 671216.19 | AA8: =C8+G8+K8+O8+S8+W8 -> 699929.07 | AB8: =D8+H8+L8+P8+T8+X8 -> 749566.18 | AC8: =E8+I8+M8+Q8+U8+Y8 -> 785385.05
A9: Perdagangan Besar dan Eceran; Reparasi Mobil dan Sepeda Motor | B9: 8779.73 | C9: 9159.47 | D9: 9521.98 | E9: 10024.25 | F9: 64030.67 | G9: 66574.78 | H9: 69454.87 | I9: 72655.41 | J9: 307754.12 | K9: 321661.05 | L9: 343770.7 | M9: 362681.18 | N9: 230532.56 | O9: 240583.84 | P9: 252244.61 | Q9: 264862.53 | R9: 153670.44 | S9: 161240.41 | T9: 167931.17 | U9: 175700.39 | V9: 333626.69 | W9: 352837.67 | X9: 368875.69 | Y9: 383580.62 | Z9: =B9+F9+J9+N9+R9+V9 -> 1098394.2 | AA9: =C9+G9+K9+O9+S9+W9 -> 1152057.2 | AB9: =D9+H9+L9+P9+T9+X9 -> 1211799 | AC9: =E9+I9+M9+Q9+U9+Y9 -> 1269504.4
A10: Transportasi dan Pergudangan | B10: 5287.74 | C10: 5822.82 | D10: 6186.17 | E10: 6530.34 | F10: 27947.76 | G10: 31433.2 | H10: 33428.91 | I10: 34833.14 | J10: 74214.76 | K10: 84642.25 | L10: 90533.4 | M10: 98400.67 | N10: 75521.57 | O10: 83777.21 | P10: 94113.89 | Q10: 104938.19 | R10: 42103.03 | S10: 45523.39 | T10: 48052.76 | U10: 51285.06 | V10: 53240.33 | W10: 60314.16 | X10: 66044.82 | Y10: 70889.1 | Z10: =B10+F10+J10+N10+R10+V10 -> 278315.19 | AA10: =C10+G10+K10+O10+S10+W10 -> 311513.03 | AB10: =D10+H10+L10+P10+T10+X10 -> 338359.95 | AC10: =E10+I10+M10+Q10+U10+Y10 -> 366876.5
A11: Penyediaan Akomodasi dan Makan Minum | B11: 10259.81 | C11: 11173.46 | D11: 12131.02 | E11: 12899.6 | F11: 12249.58 | G11: 13284.07 | H11: 14221.36 | I11: 15157.59 | J11: 91152.68 | K11: 99983.06 | L11: 108295.65 | M11: 118398.38 | N11: 42972.84 | O11: 46721.89 | P11: 49724.89 | Q11: 54866.88 | R11: 38132.45 | S11: 42417.2 | T11: 46670.27 | U11: 51617.3 | V11: 9452.21 | W11: 101732.19 | X11: 108833.45 | Y11: 117602.95 | Z11: =B11+F11+J11+N11+R11+V11 -> 204219.57 | AA11: =C11+G11+K11+O11+S11+W11 -> 315311.87 | AB11: =D11+H11+L11+P11+T11+X11 -> 339876.64 | AC11: =E11+I11+M11+Q11+U11+Y11 -> 370542.7
A12: Informasi dan Komunikasi | B12: 16907.39 | C12: 17631.3 | D12: 18396.74 | E12: 19195.07 | F12: 33161.9 | G12: 35734.64 | H12: 37823.43 | I12: 39950.35 | J12: 262247.28 | K12: 281781.27 | L12: 295297.83 | M12: 313673.07 | N12: 97480.64 | O12: 105146 | P12: 113765.59 | Q12: 124147.98 | R12: 63846.51 | S12: 70658.78 | T12: 77416.08 | U12: 84182.23 | V12: 119126.09 | W12: 126994.5 | X12: 135158.83 | Y12: 145374.43 | Z12: =B12+F12+J12+N12+R12+V12 -> 592769.81 | AA12: =C12+G12+K12+O12+S12+W12 -> 637946.49 | AB12: =D12+H12+L12+P12+T12+X12 -> 677858.5 | AC12: =E12+I12+M12+Q12+U12+Y12 -> 726523.13
A13: Jasa Keuangan dan Asuransi | B13: 4018.73 | C13: 4432.25 | D13: 4721.39 | E13: 4794.84 | F13: 14912.11 | G13: 14810 | H13: 14850.57 | I13: 14594.36 | J13: 210508.45 | K13: 221857.65 | L13: 233740.3 | M13: 242701.8 | N13: 38743.11 | O13: 40184.13 | P13: 41870.17 | Q13: 43238.82 | R13: 27690.76 | S13: 28289.1 | T13: 28899.58 | U13: 30519.47 | V13: 43096.15 | W13: 44731.09 | X13: 46473.15 | Y13: 47512.44 | Z13: =B13+F13+J13+N13+R13+V13 -> 338969.31 | AA13: =C13+G13+K13+O13+S13+W13 -> 354304.22 | AB13: =D13+H13+L13+P13+T13+X13 -> 370555.16 | AC13: =E13+I13+M13+Q13+U13+Y13 -> 383361.73
A14: Real Estate | B14: 7864.69 | C14: 8155.53 | D14: 8487.82 | E14: 8831.62 | F14: 44509.24 | G14: 46071.63 | H14: 47716.22 | I14: 50549.62 | J14: 122960.43 | K14: 123874.01 | L14: 125748.53 | M14: 129233.11 | N14: 22993.05 | O14: 24426.12 | P14: 26046.99 | Q14: 28187.87 | R14: 20107.1 | S14: 21494.52 | T14: 22764.06 | U14: 24042.7 | V14: 31618.65 | W14: 32469.01 | X14: 33414.39 | Y14: 34538.09 | Z14: =B14+F14+J14+N14+R14+V14 -> 250053.16 | AA14: =C14+G14+K14+O14+S14+W14 -> 256490.82 | AB14: =D14+H14+L14+P14+T14+X14 -> 264178.01 | AC14: =E14+I14+M14+Q14+U14+Y14 -> 275383.01
... A19: Jasa Lainnya | B19: 3412.77 | C19: 3652.74 | D19: 3775.49 | E19: 4048.02 | F19: 7198 | G19: 7873.42 | H19: 8270.15 | I19: 8731.87 | J19: 78134.58 | K19: 87201.78 | L19: 91930.32 | M19: 99711.9 | N19: 35559.49 | O19: 38253.41 | P19: 41286.15 | Q19: 44975.22 | R19: 17963.16 | S19: 19294.49 | T19: 20609.68 | U19: 22288.53 | V19: 24250.11 | W19: 26492.18 | X19: 28759.88 | Y19: 31037.36 | Z19: =B19+F19+J19+N19+R19+V19 -> 166518.11 | AA19: =C19+G19+K19+O19+S19+W19 -> 182768.02 | AB19: =D19+H19+L19+P19+T19+X19 -> 194631.67 | AC19: =E19+I19+M19+Q19+U19+Y19 -> 210792.9
A20: TOTAL | B20: =SUM(B3:B19) -> 112901.34 | C20: =SUM(C3:C19) -> 118625.55 | D20: =SUM(D3:D19) -> 124590.44 | E20: =SUM(E3:E19) -> 131435.93 | F20: =SUM(F3:F19) -> 484131.21 | G20: =SUM(G3:G19) -> 507425.74 | H20: =SUM(H3:H19) -> 531735.24 | I20: =SUM(I3:I19) -> 560270.88 | ... O20: =SUM(O3:O19) -> 1669416.9 | P20: 1752124.2 | Q20: =SUM(Q3:Q19) -> 1845316.7 | R20: =SUM(R3:R19) -> 1050278.1 | S20: =SUM(S3:S19) -> 1102437.5 | T20: =SUM(T3:T19) -> 1156998.9 | U20: =SUM(U3:U19) -> 1219148.6 | V20: =SUM(V3:V19) -> 1673174.9 | W20: =SUM(W3:W19) -> 1844808.7 | X20: =SUM(X3:X19) -> 1935810.1 | ... AC20: =SUM(AC3:AC19) -> 8058370.8
A24: Satuan Milyar rupiah | B24: DIY | F24: TOTAL JAWA | J24: GI/G | N24: LQ
B25: 2022 | C25: 2023 | D25: 2024 | E25: 2025 | F25: 2022 | G25: 2023 | H25: 2024 | I25: 2025 | J25: 2022 | K25: 2023 | L25: 2024 | M25: 2025 | N25: 2022 | O25: 2023 | P25: 2024 | Q25: 2025
A26: Pertanian. Kehutanan. dan Perikanan | C26: =(C3-B3)/B3 -> 0.012807096 | D26: =(D3-C3)/C3 -> 0.0013541381 | E26: =(E3-D3)/D3 -> 0.063579062 | G26: =(AA3-Z3)/Z3 -> 0.01036702 | H26: =(AB3-AA3)/AA3 -> 0.0087652703 | I26: =(AC3-AB3)/AB3 -> 0.064737535 | K26: =C26/G26 -> 1.235369 | L26: =D26/H26 -> 0.15448903 | M26: =E26/I26 -> 0.98210508 | O26: ='LQ ADHK'!L26 -> 1.1698208 | P26: ='LQ ADHK'!M26 -> 1.2199683 | Q26: ='LQ ADHK'!N26 -> 1.2164706 | R26: =IF(AND($M26>1,$Q26>1),"Maju Pesat", IF(AND($M26>1,$Q26<1),"Potensial", IF(AND($M26<1,$Q26>1),"Maju Tertekan",IF(AND($M26<1,$Q26<1),"Tertinggal")))) -> Maju Tertekan | S26: =IF(R26="Maju Pesat","Kuadran I", IF(R26="Potensial","Kuadran III", IF(R26="Maju Tertekan","Kuadran II", "Kuadran IV"))) -> Kuadran II
A27: Pertambangan dan Penggalian | C27: =(C4-B4)/B4 -> 0.032532982 | D27: =(D4-C4)/C4 -> 0.077455396 | E27: =(E4-D4)/D4 -> 0.062020093 | G27: =(AA4-Z4)/Z4 -> 0.0066098787 | H27: =(AB4-AA4)/AA4 -> -0.00073358685 | I27: =(AC4-AB4)/AB4 -> 0.011008779 | K27: =C27/G27 -> 4.9218728 | L27: =D27/H27 -> -105.58449 | M27: =E27/I27 -> 5.633694 | O27: ='LQ ADHK'!L27 -> 0.24576723 | P27: ='LQ ADHK'!M27 -> 0.27944195 | Q27: ='LQ ADHK'!N27 -> 0.29301866 | R27: =IF(AND($E27>I$43,$Q27>1),"Maju Pesat", IF(AND($E27>I$43,$Q27<1),"Potensial", IF(AND($E27<I$43,$Q27>1),"Maju Tertekan",IF(AND($E27<I$43,$Q27<1),"Tertinggal")))) -> Potensial | S27: =IF(R27="Maju Pesat","Kuadran I", IF(R27="Potensial","Kuadran III", IF(R27="Maju Tertekan","Kuadran II", "Kuadran IV"))) -> Kuadran III
